
*******2017-05-03 11:11:21.656000*************
 no new datas have been crawed :http://xm.anjuke.com/sale/p1/#filtersort. 

               *******craw_oneurl*******,error record by @mylog on 2017-05-06 22:16:09.623000*************
Traceback (most recent call last):
  File "C:\git\python-craw\spider\mytools.py", line 11, in _deco
    return func(*a,**b)
  File "C:\git\python-craw\house4.py", line 79, in craw_oneurl
    new_urls,new_datas = self.parser.parse(html_cont,from_)
  File "C:\git\python-craw\spider\html_parser.py", line 38, in parse
    return new_urls,new_datas
UnboundLocalError: local variable 'new_urls' referenced before assignment
2017-05-06 22:17:38.063000record by program 
<class '_mysql_exceptions.Error'> : (1366, u"Incorrect string value: '\\xF1\\xA1\\xBB\\xB4) ...' for column 'title' at row 1") 
 floor_index: 2
 total_floor: 15
 community_name: 祥店新村
 details_url: http://xm.anjuke.com/prop/view/A827919904
Traceback (most recent call last):
  File "C:\git\python-craw\spider\html_outputer.py", line 187, in out_local_mysql
    data['details_url'],data['community_name'],datetime.date.today(),data['from']))
  File "C:\Python27\lib\site-packages\pymysql\cursors.py", line 166, in execute
    result = self._query(query)
  File "C:\Python27\lib\site-packages\pymysql\cursors.py", line 322, in _query
    conn.query(q)
  File "C:\Python27\lib\site-packages\pymysql\connections.py", line 856, in query
    self._affected_rows = self._read_query_result(unbuffered=unbuffered)
  File "C:\Python27\lib\site-packages\pymysql\connections.py", line 1057, in _read_query_result
    result.read()
  File "C:\Python27\lib\site-packages\pymysql\connections.py", line 1340, in read
    first_packet = self.connection._read_packet()
  File "C:\Python27\lib\site-packages\pymysql\connections.py", line 1014, in _read_packet
    packet.check_error()
  File "C:\Python27\lib\site-packages\pymysql\connections.py", line 393, in check_error
    err.raise_mysql_exception(self._data)
  File "C:\Python27\lib\site-packages\pymysql\err.py", line 107, in raise_mysql_exception
    raise errorclass(errno, errval)
InternalError: (1366, u"Incorrect string value: '\\xF1\\xA1\\xBB\\xB4) ...' for column 'title' at row 1")

*******get_content urlopen error record by get_content 2017-05-06 22:17:58.631000*************
2017-05-06 22:17:58.631000
Traceback (most recent call last):
  File "C:\git\python-craw\spider\html_downloader.py", line 41, in get_content
    data = response.read()
  File "C:\Python27\lib\socket.py", line 355, in read
    data = self._sock.recv(rbufsize)
  File "C:\Python27\lib\httplib.py", line 573, in read
    return self._read_chunked(amt)
  File "C:\Python27\lib\httplib.py", line 642, in _read_chunked
    value.append(self._safe_read(chunk_left))
  File "C:\Python27\lib\httplib.py", line 688, in _safe_read
    chunk = self.fp.read(min(amt, MAXAMOUNT))
  File "C:\Python27\lib\socket.py", line 384, in read
    data = self._sock.recv(left)
timeout: timed out

*******get_content urlopen error record by get_content 2017-05-07 08:10:38.564000*************
2017-05-07 08:10:38.564000
Traceback (most recent call last):
  File "C:\git\python-craw\spider\html_downloader.py", line 34, in get_content
    response = urllib2.urlopen(request,timeout=10)
  File "C:\Python27\lib\urllib2.py", line 154, in urlopen
    return opener.open(url, data, timeout)
  File "C:\Python27\lib\urllib2.py", line 435, in open
    response = meth(req, response)
  File "C:\Python27\lib\urllib2.py", line 548, in http_response
    'http', request, response, code, msg, hdrs)
  File "C:\Python27\lib\urllib2.py", line 467, in error
    result = self._call_chain(*args)
  File "C:\Python27\lib\urllib2.py", line 407, in _call_chain
    result = func(*args)
  File "C:\Python27\lib\urllib2.py", line 654, in http_error_302
    return self.parent.open(new, timeout=req.timeout)
  File "C:\Python27\lib\urllib2.py", line 435, in open
    response = meth(req, response)
  File "C:\Python27\lib\urllib2.py", line 548, in http_response
    'http', request, response, code, msg, hdrs)
  File "C:\Python27\lib\urllib2.py", line 473, in error
    return self._call_chain(*args)
  File "C:\Python27\lib\urllib2.py", line 407, in _call_chain
    result = func(*args)
  File "C:\Python27\lib\urllib2.py", line 556, in http_error_default
    raise HTTPError(req.get_full_url(), code, msg, hdrs, fp)
HTTPError: HTTP Error 404: Not Found

*******get_content urlopen error record by get_content 2017-05-07 08:13:49.864000*************
2017-05-07 08:13:49.864000
Traceback (most recent call last):
  File "C:\git\python-craw\spider\html_downloader.py", line 34, in get_content
    response = urllib2.urlopen(request,timeout=10)
  File "C:\Python27\lib\urllib2.py", line 154, in urlopen
    return opener.open(url, data, timeout)
  File "C:\Python27\lib\urllib2.py", line 435, in open
    response = meth(req, response)
  File "C:\Python27\lib\urllib2.py", line 548, in http_response
    'http', request, response, code, msg, hdrs)
  File "C:\Python27\lib\urllib2.py", line 467, in error
    result = self._call_chain(*args)
  File "C:\Python27\lib\urllib2.py", line 407, in _call_chain
    result = func(*args)
  File "C:\Python27\lib\urllib2.py", line 654, in http_error_302
    return self.parent.open(new, timeout=req.timeout)
  File "C:\Python27\lib\urllib2.py", line 435, in open
    response = meth(req, response)
  File "C:\Python27\lib\urllib2.py", line 548, in http_response
    'http', request, response, code, msg, hdrs)
  File "C:\Python27\lib\urllib2.py", line 473, in error
    return self._call_chain(*args)
  File "C:\Python27\lib\urllib2.py", line 407, in _call_chain
    result = func(*args)
  File "C:\Python27\lib\urllib2.py", line 556, in http_error_default
    raise HTTPError(req.get_full_url(), code, msg, hdrs, fp)
HTTPError: HTTP Error 404: Not Found
